<mujoco>
  <option timestep="0.001" />
  <asset>
    <texture builtin="gradient" height="100" rgb1="1 1 1" rgb2="0 0 0" type="skybox" width="100"/>
    <texture builtin="flat" height="1278" mark="cross" markrgb="1 1 1" name="texgeom" random="0.01" rgb1="0.8 0.6 0.4" rgb2="0.8 0.6 0.4" type="cube" width="127"/>
    <texture builtin="checker" height="100" name="texplane" rgb1="0 0 0" rgb2="0.8 0.8 0.8" type="2d" width="100"/>
    <material name="MatPlane" reflectance="0.5" shininess="1" specular="1" texrepeat="30 30" texture="texplane"/>
    <material name="geom" texture="texgeom" texuniform="true"/>
  </asset>
   <worldbody>
     <light cutoff="100" diffuse="1 1 1" dir="-0 0 -1.3" directional="true" exponent="1" pos="0 0 1.3" specular=".1 .1 .1"/>
     <geom conaffinity="1" condim="3" material="MatPlane" name="floor" pos="0 0 0" rgba="0.8 0.9 0.8 1" size="40 40 40" type="plane"/>
      <body name="mainframe" euler="0 0 0"  pos="0 0 1">
      	<joint type="free"/>
      	<geom type="box" size=".22 .71 .16" pos="0 0 0.19" rgba="1 0 0 1"/>    //Base Frame
        <geom type="box" size=".01 .35 .65" pos="0 0 0.93" rgba="0 0 1 1"/>        //PCB
        <geom type="box" size=".08 0.38 .25" pos="0.034 0 1.34" rgba="1 0 0 1"/> 	//Battery holder
        <site type="box" size="0.01 .01 .01" pos="0 0 0.1" rgba=".9 .1 .9 1" name="IMU"/>  //Sensor
        <body name="lwheel" pos="0 0 0">
      		  <joint axis="0 1 0" name="lmotor" pos="0 -0.87 0" range="-.52 1.05" damping="50" type="hinge"/>//stiffness="240" type="hinge"/>
      	  	<geom type="cylinder" euler="90 0 0" size=".7 .14 " pos="0 -0.87 0" rgba="0.128 0.128 0.128 1"/>
      	</body>
      	<body name="rwheel" pos="0 0 0">
		        <joint axis="0 -1 0" name="rmotor" pos="0 0.87 0" range="-.52 1.05" damping="50" type="hinge"/>//stiffness="240" type="hinge"/>
            <geom type="cylinder" euler="90 0 0" size=".7 .14 " pos="0 0.87 0" rgba="0.128 0.128 0.1280 1"/>
      	</body>
      </body>
    </worldbody>
    <sensor>
          <accelerometer name="Acc" site="IMU" />
          <gyro name="Gyro" site="IMU" />
          <jointpos name="Lencoder" joint="lmotor"/>
	        <jointpos name="Rencoder" joint="rmotor"/>//framequat name="Angle" objname="IMU" objtype="site" />
    </sensor>
    <actuator>
    	<motor  gear="30" joint="lmotor" name="almotor"/>// gaintype="user" gainrpm="1 0 0"name="almotor"/>
   	  <motor  gear="30" joint="rmotor" name="armotor"/>
    </actuator>
</mujoco>
